Workbook
Name SegmentaçãodeDados_Aux_Ano: #N/A
Name SegmentaçãodeDados_Aux_Mês: #N/A

Sheet Inspeção
A1: PAINEL DE RESULTADOS
A2: PLACA | B2: PREFIXO | C2: KM RODADO | D2: TOTAL DE LITROS | E2: GASTO TOTAL | F2: PREÇO MÉDIO | G2: CUSTO/KM | H2: MÉDIA
A3: TTP5B47 | B3: IT-02 | C3: =IFERROR(VLOOKUP(Tabela204[[#This Row],[PLACA]],Resultados!$B$7:$H$121,3,0),"-") -> 178151 | D3: =IFERROR(VLOOKUP(Tabela204[[#This Row],[PLACA]],Resultados!$B$7:$H$121,4,0),"-") -> 17876.35 | E3: =IFERROR(VLOOKUP(Tabela204[[#This Row],[PLACA]],Resultados!$B$7:$H$121,5,0),"-") -> 83465 | F3: =IFERROR(Tabela204[[#This Row],[GASTO TOTAL]]/Tabela204[[#This Row],[TOTAL DE LITROS]],"-") -> 4.669018 | G3: =IFERROR(Tabela204[[#This Row],[GASTO TOTAL]]/Tabela204[[#This Row],[KM RODADO]],"-") -> 0.46850705 | H3: =IFERROR(Tabela204[[#This Row],[KM RODADO]]/Tabela204[[#This Row],[TOTAL DE LITROS]],"-") -> 9.9657369
A4: TTT2H93 | B4: IT-03 | C4: =IFERROR(VLOOKUP(Tabela204[[#This Row],[PLACA]],Resultados!$B$7:$H$121,3,0),"-") -> 80365 | D4: =IFERROR(VLOOKUP(Tabela204[[#This Row],[PLACA]],Resultados!$B$7:$H$121,4,0),"-") -> 8075.4 | E4: =IFERROR(VLOOKUP(Tabela204[[#This Row],[PLACA]],Resultados!$B$7:$H$121,5,0),"-") -> 37087.56 | F4: =IFERROR(Tabela204[[#This Row],[GASTO TOTAL]]/Tabela204[[#This Row],[TOTAL DE LITROS]],"-") -> 4.5926592 | G4: =IFERROR(Tabela204[[#This Row],[GASTO TOTAL]]/Tabela204[[#This Row],[KM RODADO]],"-") -> 0.46148896 | H4: =IFERROR(Tabela204[[#This Row],[KM RODADO]]/Tabela204[[#This Row],[TOTAL DE LITROS]],"-") -> 9.951829
A5: TUB2B84 | B5: IT-04 | C5: =IFERROR(VLOOKUP(Tabela204[[#This Row],[PLACA]],Resultados!$B$7:$H$121,3,0),"-") -> 26096 | D5: =IFERROR(VLOOKUP(Tabela204[[#This Row],[PLACA]],Resultados!$B$7:$H$121,4,0),"-") -> 2688.63 | E5: =IFERROR(VLOOKUP(Tabela204[[#This Row],[PLACA]],Resultados!$B$7:$H$121,5,0),"-") -> 11697.98 | F5: =IFERROR(Tabela204[[#This Row],[GASTO TOTAL]]/Tabela204[[#This Row],[TOTAL DE LITROS]],"-") -> 4.3509073 | G5: =IFERROR(Tabela204[[#This Row],[GASTO TOTAL]]/Tabela204[[#This Row],[KM RODADO]],"-") -> 0.44826717 | H5: =IFERROR(Tabela204[[#This Row],[KM RODADO]]/Tabela204[[#This Row],[TOTAL DE LITROS]],"-") -> 9.7060585
A6: SQZ2J86 | B6: IT-04.1 | C6: =IFERROR(VLOOKUP(Tabela204[[#This Row],[PLACA]],Resultados!$B$7:$H$121,3,0),"-") -> 20743 | D6: =IFERROR(VLOOKUP(Tabela204[[#This Row],[PLACA]],Resultados!$B$7:$H$121,4,0),"-") -> 2415.39 | E6: =IFERROR(VLOOKUP(Tabela204[[#This Row],[PLACA]],Resultados!$B$7:$H$121,5,0),"-") -> 11591.9 | F6: =IFERROR(Tabela204[[#This Row],[GASTO TOTAL]]/Tabela204[[#This Row],[TOTAL DE LITROS]],"-") -> 4.7991836 | G6: =IFERROR(Tabela204[[#This Row],[GASTO TOTAL]]/Tabela204[[#This Row],[KM RODADO]],"-") -> 0.55883431 | H6: =IFERROR(Tabela204[[#This Row],[KM RODADO]]/Tabela204[[#This Row],[TOTAL DE LITROS]],"-") -> 8.5878471
A7: TTR3A31 | B7: IT-05 | C7: =IFERROR(VLOOKUP(Tabela204[[#This Row],[PLACA]],Resultados!$B$7:$H$121,3,0),"-") -> 165129 | D7: =IFERROR(VLOOKUP(Tabela204[[#This Row],[PLACA]],Resultados!$B$7:$H$121,4,0),"-") -> 16829.18 | E7: =IFERROR(VLOOKUP(Tabela204[[#This Row],[PLACA]],Resultados!$B$7:$H$121,5,0),"-") -> 78302.72 | F7: =IFERROR(Tabela204[[#This Row],[GASTO TOTAL]]/Tabela204[[#This Row],[TOTAL DE LITROS]],"-") -> 4.6527947 | G7: =IFERROR(Tabela204[[#This Row],[GASTO TOTAL]]/Tabela204[[#This Row],[KM RODADO]],"-") -> 0.47419121 | H7: =IFERROR(Tabela204[[#This Row],[KM RODADO]]/Tabela204[[#This Row],[TOTAL DE LITROS]],"-") -> 9.8120645
A8: TUG2C45 | B8: IT-06 | C8: =IFERROR(VLOOKUP(Tabela204[[#This Row],[PLACA]],Resultados!$B$7:$H$121,3,0),"-") -> 172506 | D8: =IFERROR(VLOOKUP(Tabela204[[#This Row],[PLACA]],Resultados!$B$7:$H$121,4,0),"-") -> 17542.44 | E8: =IFERROR(VLOOKUP(Tabela204[[#This Row],[PLACA]],Resultados!$B$7:$H$121,5,0),"-") -> 83130.99 | F8: =IFERROR(Tabela204[[#This Row],[GASTO TOTAL]]/Tabela204[[#This Row],[TOTAL DE LITROS]],"-") -> 4.7388499 | G8: =IFERROR(Tabela204[[#This Row],[GASTO TOTAL]]/Tabela204[[#This Row],[KM RODADO]],"-") -> 0.48190202 | H8: =IFERROR(Tabela204[[#This Row],[KM RODADO]]/Tabela204[[#This Row],[TOTAL DE LITROS]],"-") -> 9.8336377
A9: TUF2B45 | B9: IT-07 | C9: =IFERROR(VLOOKUP(Tabela204[[#This Row],[PLACA]],Resultados!$B$7:$H$121,3,0),"-") -> 159547 | D9: =IFERROR(VLOOKUP(Tabela204[[#This Row],[PLACA]],Resultados!$B$7:$H$121,4,0),"-") -> 16920.52 | E9: =IFERROR(VLOOKUP(Tabela204[[#This Row],[PLACA]],Resultados!$B$7:$H$121,5,0),"-") -> 78466.47 | F9: =IFERROR(Tabela204[[#This Row],[GASTO TOTAL]]/Tabela204[[#This Row],[TOTAL DE LITROS]],"-") -> 4.6373557 | G9: =IFERROR(Tabela204[[#This Row],[GASTO TOTAL]]/Tabela204[[#This Row],[KM RODADO]],"-") -> 0.49180787 | H9: =IFERROR(Tabela204[[#This Row],[KM RODADO]]/Tabela204[[#This Row],[TOTAL DE LITROS]],"-") -> 9.4292019
A10: TTQ7B47 | B10: IT-07.1 | C10: =IFERROR(VLOOKUP(Tabela204[[#This Row],[PLACA]],Resultados!$B$7:$H$121,3,0),"-") -> 1767 | D10: =IFERROR(VLOOKUP(Tabela204[[#This Row],[PLACA]],Resultados!$B$7:$H$121,4,0),"-") -> 196.98 | E10: =IFERROR(VLOOKUP(Tabela204[[#This Row],[PLACA]],Resultados!$B$7:$H$121,5,0),"-") -> 943.94 | F10: =IFERROR(Tabela204[[#This Row],[GASTO TOTAL]]/Tabela204[[#This Row],[TOTAL DE LITROS]],"-") -> 4.7920601 | G10: =IFERROR(Tabela204[[#This Row],[GASTO TOTAL]]/Tabela204[[#This Row],[KM RODADO]],"-") -> 0.53420487 | H10: =IFERROR(Tabela204[[#This Row],[KM RODADO]]/Tabela204[[#This Row],[TOTAL DE LITROS]],"-") -> 8.9704539
A11: TTY2C25 | B11: IT-08 | C11: =IFERROR(VLOOKUP(Tabela204[[#This Row],[PLACA]],Resultados!$B$7:$H$121,3,0),"-") -> 155011 | D11: =IFERROR(VLOOKUP(Tabela204[[#This Row],[PLACA]],Resultados!$B$7:$H$121,4,0),"-") -> 16588.6 | E11: =IFERROR(VLOOKUP(Tabela204[[#This Row],[PLACA]],Resultados!$B$7:$H$121,5,0),"-") -> 78350.78 | F11: =IFERROR(Tabela204[[#This Row],[GASTO TOTAL]]/Tabela204[[#This Row],[TOTAL DE LITROS]],"-") -> 4.7231701 | G11: =IFERROR(Tabela204[[#This Row],[GASTO TOTAL]]/Tabela204[[#This Row],[KM RODADO]],"-") -> 0.50545303 | H11: =IFERROR(Tabela204[[#This Row],[KM RODADO]]/Tabela204[[#This Row],[TOTAL DE LITROS]],"-") -> 9.3444293
A12: TTQ3C61 | B12: IT-10 R | C12: =IFERROR(VLOOKUP(Tabela204[[#This Row],[PLACA]],Resultados!$B$7:$H$121,3,0),"-") -> 66958 | D12: =IFERROR(VLOOKUP(Tabela204[[#This Row],[PLACA]],Resultados!$B$7:$H$121,4,0),"-") -> 6473.82 | E12: =IFERROR(VLOOKUP(Tabela204[[#This Row],[PLACA]],Resultados!$B$7:$H$121,5,0),"-") -> 29782.35 | F12: =IFERROR(Tabela204[[#This Row],[GASTO TOTAL]]/Tabela204[[#This Row],[TOTAL DE LITROS]],"-") -> 4.6004291 | G12: =IFERROR(Tabela204[[#This Row],[GASTO TOTAL]]/Tabela204[[#This Row],[KM RODADO]],"-") -> 0.44479151 | H12: =IFERROR(Tabela204[[#This Row],[KM RODADO]]/Tabela204[[#This Row],[TOTAL DE LITROS]],"-") -> 10.342889
A13: TTT2H95 | B13: IT-11 R | C13: =IFERROR(VLOOKUP(Tabela204[[#This Row],[PLACA]],Resultados!$B$7:$H$121,3,0),"-") -> 159620 | D13: =IFERROR(VLOOKUP(Tabela204[[#This Row],[PLACA]],Resultados!$B$7:$H$121,4,0),"-") -> 15718.96 | E13: =IFERROR(VLOOKUP(Tabela204[[#This Row],[PLACA]],Resultados!$B$7:$H$121,5,0),"-") -> 74928.19 | F13: =IFERROR(Tabela204[[#This Row],[GASTO TOTAL]]/Tabela204[[#This Row],[TOTAL DE LITROS]],"-") -> 4.7667397 | G13: =IFERROR(Tabela204[[#This Row],[GASTO TOTAL]]/Tabela204[[#This Row],[KM RODADO]],"-") -> 0.46941605 | H13: =IFERROR(Tabela204[[#This Row],[KM RODADO]]/Tabela204[[#This Row],[TOTAL DE LITROS]],"-") -> 10.154616
A14: TUQ2H91 | B14: IT-13 | C14: =IFERROR(VLOOKUP(Tabela204[[#This Row],[PLACA]],Resultados!$B$7:$H$121,3,0),"-") -> 50898 | D14: =IFERROR(VLOOKUP(Tabela204[[#This Row],[PLACA]],Resultados!$B$7:$H$121,4,0),"-") -> 5814.4 | E14: =IFERROR(VLOOKUP(Tabela204[[#This Row],[PLACA]],Resultados!$B$7:$H$121,5,0),"-") -> 27498.96 | F14: =IFERROR(Tabela204[[#This Row],[GASTO TOTAL]]/Tabela204[[#This Row],[TOTAL DE LITROS]],"-") -> 4.7294579 | G14: =IFERROR(Tabela204[[#This Row],[GASTO TOTAL]]/Tabela204[[#This Row],[KM RODADO]],"-") -> 0.54027585 | H14: =IFERROR(Tabela204[[#This Row],[KM RODADO]]/Tabela204[[#This Row],[TOTAL DE LITROS]],"-") -> 8.7537837
... A19: TUK2D26 | B19: VIA-12 R | C19: =IFERROR(VLOOKUP(Tabela204[[#This Row],[PLACA]],Resultados!$B$7:$H$121,3,0),"-") -> 99085 | D19: =IFERROR(VLOOKUP(Tabela204[[#This Row],[PLACA]],Resultados!$B$7:$H$121,4,0),"-") -> 7310.91 | E19: =IFERROR(VLOOKUP(Tabela204[[#This Row],[PLACA]],Resultados!$B$7:$H$121,5,0),"-") -> 44741.68 | F19: =IFERROR(Tabela204[[#This Row],[GASTO TOTAL]]/Tabela204[[#This Row],[TOTAL DE LITROS]],"-") -> 6.119851 | G19: =IFERROR(Tabela204[[#This Row],[GASTO TOTAL]]/Tabela204[[#This Row],[KM RODADO]],"-") -> 0.45154847 | H19: =IFERROR(Tabela204[[#This Row],[KM RODADO]]/Tabela204[[#This Row],[TOTAL DE LITROS]],"-") -> 13.553032
D22: =SUBTOTAL(109,D3:D20) -> 173250.18 | E22: =SUBTOTAL(109,E3:E20) -> 883424.58 | G22: =SUBTOTAL(1,Tabela204[[#All],[CUSTO/KM]]) -> 0.48805919 | H22: =SUBTOTAL(1,Tabela204[MÉDIA]) -> 10.555397
D24: Preço Médio = | E24: =E22/D22 -> 5.0991265

Sheet Resgate
A1: PAINEL DE RESULTADOS
A2: PLACA | B2: PREFIXO | C2: KM RODADO | D2: TOTAL DE LITROS | E2: GASTO TOTAL | F2: PREÇO MÉDIO | G2: CUSTO/KM | H2: MÉDIA
A3: TFV8C74 | B3: A01 | C3: =IFERROR(VLOOKUP(Tabela205[[#This Row],[PLACA]],Resultados!$B$7:$H$121,3,0),"-") -> 19232 | D3: =IFERROR(VLOOKUP(Tabela205[[#This Row],[PLACA]],Resultados!$B$7:$H$121,4,0),"-") -> 3505.55 | E3: =IFERROR(VLOOKUP(Tabela205[[#This Row],[PLACA]],Resultados!$B$7:$H$121,5,0),"-") -> 23526.06 | F3: =IFERROR(E3/D3,"-") -> 6.7110896 | G3: =IFERROR(Tabela205[[#This Row],[GASTO TOTAL]]/Tabela205[[#This Row],[KM RODADO]],"-") -> 1.2232768 | H3: =IFERROR(Tabela205[[#This Row],[KM RODADO]]/Tabela205[[#This Row],[TOTAL DE LITROS]],"-") -> 5.4861577
A4: TFM4H34 | B4: A02 | C4: =IFERROR(VLOOKUP(Tabela205[[#This Row],[PLACA]],Resultados!$B$7:$H$121,3,0),"-") -> 14412 | D4: =IFERROR(VLOOKUP(Tabela205[[#This Row],[PLACA]],Resultados!$B$7:$H$121,4,0),"-") -> 2465.43 | E4: =IFERROR(VLOOKUP(Tabela205[[#This Row],[PLACA]],Resultados!$B$7:$H$121,5,0),"-") -> 16410.42 | F4: =IFERROR(E4/D4,"-") -> 6.6562101 | G4: =IFERROR(Tabela205[[#This Row],[GASTO TOTAL]]/Tabela205[[#This Row],[KM RODADO]],"-") -> 1.1386636 | H4: =IFERROR(Tabela205[[#This Row],[KM RODADO]]/Tabela205[[#This Row],[TOTAL DE LITROS]],"-") -> 5.8456334
A5: TGC9A34 | B5: R01 | C5: =IFERROR(VLOOKUP(Tabela205[[#This Row],[PLACA]],Resultados!$B$7:$H$121,3,0),"-") -> 20688 | D5: =IFERROR(VLOOKUP(Tabela205[[#This Row],[PLACA]],Resultados!$B$7:$H$121,4,0),"-") -> 3840.83 | E5: =IFERROR(VLOOKUP(Tabela205[[#This Row],[PLACA]],Resultados!$B$7:$H$121,5,0),"-") -> 24633.62 | F5: =IFERROR(E5/D5,"-") -> 6.4136189 | G5: =IFERROR(Tabela205[[#This Row],[GASTO TOTAL]]/Tabela205[[#This Row],[KM RODADO]],"-") -> 1.1907202 | H5: =IFERROR(Tabela205[[#This Row],[KM RODADO]]/Tabela205[[#This Row],[TOTAL DE LITROS]],"-") -> 5.3863358
A6: TGL2B04 | B6: R03 | C6: =IFERROR(VLOOKUP(Tabela205[[#This Row],[PLACA]],Resultados!$B$7:$H$121,3,0),"-") -> 11757 | D6: =IFERROR(VLOOKUP(Tabela205[[#This Row],[PLACA]],Resultados!$B$7:$H$121,4,0),"-") -> 2291.05 | E6: =IFERROR(VLOOKUP(Tabela205[[#This Row],[PLACA]],Resultados!$B$7:$H$121,5,0),"-") -> 15081.58 | F6: =IFERROR(E6/D6,"-") -> 6.5828245 | G6: =IFERROR(Tabela205[[#This Row],[GASTO TOTAL]]/Tabela205[[#This Row],[KM RODADO]],"-") -> 1.2827745 | H6: =IFERROR(Tabela205[[#This Row],[KM RODADO]]/Tabela205[[#This Row],[TOTAL DE LITROS]],"-") -> 5.1317082
A7: TFE9C14 | B7: R05 | C7: =IFERROR(VLOOKUP(Tabela205[[#This Row],[PLACA]],Resultados!$B$7:$H$121,3,0),"-") -> 11769 | D7: =IFERROR(VLOOKUP(Tabela205[[#This Row],[PLACA]],Resultados!$B$7:$H$121,4,0),"-") -> 2419.49 | E7: =IFERROR(VLOOKUP(Tabela205[[#This Row],[PLACA]],Resultados!$B$7:$H$121,5,0),"-") -> 15924.48 | F7: =IFERROR(E7/D7,"-") -> 6.5817507 | G7: =IFERROR(Tabela205[[#This Row],[GASTO TOTAL]]/Tabela205[[#This Row],[KM RODADO]],"-") -> 1.3530869 | H7: =IFERROR(Tabela205[[#This Row],[KM RODADO]]/Tabela205[[#This Row],[TOTAL DE LITROS]],"-") -> 4.8642483
A8: TGE1F64 | B8: R06 | C8: =IFERROR(VLOOKUP(Tabela205[[#This Row],[PLACA]],Resultados!$B$7:$H$121,3,0),"-") -> 18762 | D8: =IFERROR(VLOOKUP(Tabela205[[#This Row],[PLACA]],Resultados!$B$7:$H$121,4,0),"-") -> 2995.47 | E8: =IFERROR(VLOOKUP(Tabela205[[#This Row],[PLACA]],Resultados!$B$7:$H$121,5,0),"-") -> 19967.06 | F8: =IFERROR(E8/D8,"-") -> 6.665752 | G8: =IFERROR(Tabela205[[#This Row],[GASTO TOTAL]]/Tabela205[[#This Row],[KM RODADO]],"-") -> 1.0642288 | H8: =IFERROR(Tabela205[[#This Row],[KM RODADO]]/Tabela205[[#This Row],[TOTAL DE LITROS]],"-") -> 6.2634578
A9: TFW3J34 | B9: R07 | C9: =IFERROR(VLOOKUP(Tabela205[[#This Row],[PLACA]],Resultados!$B$7:$H$121,3,0),"-") -> 19360 | D9: =IFERROR(VLOOKUP(Tabela205[[#This Row],[PLACA]],Resultados!$B$7:$H$121,4,0),"-") -> 3092.59 | E9: =IFERROR(VLOOKUP(Tabela205[[#This Row],[PLACA]],Resultados!$B$7:$H$121,5,0),"-") -> 19931.27 | F9: =IFERROR(E9/D9,"-") -> 6.4448472 | G9: =IFERROR(Tabela205[[#This Row],[GASTO TOTAL]]/Tabela205[[#This Row],[KM RODADO]],"-") -> 1.0295077 | H9: =IFERROR(Tabela205[[#This Row],[KM RODADO]]/Tabela205[[#This Row],[TOTAL DE LITROS]],"-") -> 6.260125
A10: TFN3B64 | B10: R08 | C10: =IFERROR(VLOOKUP(Tabela205[[#This Row],[PLACA]],Resultados!$B$7:$H$121,3,0),"-") -> 8621 | D10: =IFERROR(VLOOKUP(Tabela205[[#This Row],[PLACA]],Resultados!$B$7:$H$121,4,0),"-") -> 1565.41 | E10: =IFERROR(VLOOKUP(Tabela205[[#This Row],[PLACA]],Resultados!$B$7:$H$121,5,0),"-") -> 10276.97 | F10: =IFERROR(E10/D10,"-") -> 6.5650341 | G10: =IFERROR(Tabela205[[#This Row],[GASTO TOTAL]]/Tabela205[[#This Row],[KM RODADO]],"-") -> 1.1920856 | H10: =IFERROR(Tabela205[[#This Row],[KM RODADO]]/Tabela205[[#This Row],[TOTAL DE LITROS]],"-") -> 5.5071834
A11: TFU6C04 | B11: R09 | C11: =IFERROR(VLOOKUP(Tabela205[[#This Row],[PLACA]],Resultados!$B$7:$H$121,3,0),"-") -> 12627 | D11: =IFERROR(VLOOKUP(Tabela205[[#This Row],[PLACA]],Resultados!$B$7:$H$121,4,0),"-") -> 3149.96 | E11: =IFERROR(VLOOKUP(Tabela205[[#This Row],[PLACA]],Resultados!$B$7:$H$121,5,0),"-") -> 20448.41 | F11: =IFERROR(E11/D11,"-") -> 6.4916412 | G11: =IFERROR(Tabela205[[#This Row],[GASTO TOTAL]]/Tabela205[[#This Row],[KM RODADO]],"-") -> 1.6194195 | H11: =IFERROR(Tabela205[[#This Row],[KM RODADO]]/Tabela205[[#This Row],[TOTAL DE LITROS]],"-") -> 4.0086223
A12: TFL8I14 | B12: R-10 R | C12: =IFERROR(VLOOKUP(Tabela205[[#This Row],[PLACA]],Resultados!$B$7:$H$121,3,0),"-") -> 16098 | D12: =IFERROR(VLOOKUP(Tabela205[[#This Row],[PLACA]],Resultados!$B$7:$H$121,4,0),"-") -> 2699.5 | E12: =IFERROR(VLOOKUP(Tabela205[[#This Row],[PLACA]],Resultados!$B$7:$H$121,5,0),"-") -> 17853.01 | F12: =IFERROR(E12/D12,"-") -> 6.6134506 | G12: =IFERROR(Tabela205[[#This Row],[GASTO TOTAL]]/Tabela205[[#This Row],[KM RODADO]],"-") -> 1.1090204 | H12: =IFERROR(Tabela205[[#This Row],[KM RODADO]]/Tabela205[[#This Row],[TOTAL DE LITROS]],"-") -> 5.9633265
D15: =SUBTOTAL(109,D3:D12) -> 28025.28 | E15: =SUBTOTAL(109,E3:E12) -> 184052.88 | G15: =SUBTOTAL(1,Tabela205[[#All],[CUSTO/KM]]) -> 1.2202784 | H15: =SUBTOTAL(1,Tabela205[MÉDIA]) -> 5.4716798
D17: Preço Médio Diesel = | E17: =E15/D15 -> 6.5673877

Sheet Pesados
A1: PAINEL DE RESULTADOS
A2: PLACA | B2: PRÉ-FIXO | C2: KM RODADO | D2: TOTAL DE LITROS | E2: GASTO TOTAL | F2: PREÇO MÉDIO | G2: CUSTO/KM | H2: MÉDIA
A3: QSW6J59 | B3: CP-01 | C3: =IFERROR(VLOOKUP(Tabela20[[#This Row],[PLACA]],Resultados!$B$7:$H$121,3,0),"-") -> 33304 | D3: =IFERROR(VLOOKUP(Tabela20[[#This Row],[PLACA]],Resultados!$B$7:$H$121,4,0),"-") -> 8783.62 | E3: =IFERROR(VLOOKUP(Tabela20[[#This Row],[PLACA]],Resultados!$B$7:$H$121,5,0),"-") -> 56791.66 | F3: =IFERROR(E3/D3,"-") -> 6.4656326 | G3: =IFERROR(Tabela20[[#This Row],[GASTO TOTAL]]/Tabela20[[#This Row],[KM RODADO]],"-") -> 1.7052504 | H3: =IFERROR(Tabela20[[#This Row],[KM RODADO]]/Tabela20[[#This Row],[TOTAL DE LITROS]],"-") -> 3.791603
A4: TIV6G27 | B4: GL-01 | C4: =IFERROR(VLOOKUP(Tabela20[[#This Row],[PLACA]],Resultados!$B$7:$H$121,3,0),"-") -> 49256 | D4: =IFERROR(VLOOKUP(Tabela20[[#This Row],[PLACA]],Resultados!$B$7:$H$121,4,0),"-") -> 8494.43 | E4: =IFERROR(VLOOKUP(Tabela20[[#This Row],[PLACA]],Resultados!$B$7:$H$121,5,0),"-") -> 54928.3 | F4: =IFERROR(E4/D4,"-") -> 6.4663903 | G4: =IFERROR(Tabela20[[#This Row],[GASTO TOTAL]]/Tabela20[[#This Row],[KM RODADO]],"-") -> 1.1151596 | H4: =IFERROR(Tabela20[[#This Row],[KM RODADO]]/Tabela20[[#This Row],[TOTAL DE LITROS]],"-") -> 5.7986233
A5: TLO0E87 | B5: GL-02 | C5: =IFERROR(VLOOKUP(Tabela20[[#This Row],[PLACA]],Resultados!$B$7:$H$121,3,0),"-") -> 47060 | D5: =IFERROR(VLOOKUP(Tabela20[[#This Row],[PLACA]],Resultados!$B$7:$H$121,4,0),"-") -> 8519.36 | E5: =IFERROR(VLOOKUP(Tabela20[[#This Row],[PLACA]],Resultados!$B$7:$H$121,5,0),"-") -> 54770.84 | F5: =IFERROR(E5/D5,"-") -> 6.4289853 | G5: =IFERROR(Tabela20[[#This Row],[GASTO TOTAL]]/Tabela20[[#This Row],[KM RODADO]],"-") -> 1.1638513 | H5: =IFERROR(Tabela20[[#This Row],[KM RODADO]]/Tabela20[[#This Row],[TOTAL DE LITROS]],"-") -> 5.5238891
A6: TJE5D27 | B6: GL-03 | C6: =IFERROR(VLOOKUP(Tabela20[[#This Row],[PLACA]],Resultados!$B$7:$H$121,3,0),"-") -> 34377 | D6: =IFERROR(VLOOKUP(Tabela20[[#This Row],[PLACA]],Resultados!$B$7:$H$121,4,0),"-") -> 6713.79 | E6: =IFERROR(VLOOKUP(Tabela20[[#This Row],[PLACA]],Resultados!$B$7:$H$121,5,0),"-") -> 46525.27 | F6: =IFERROR(E6/D6,"-") -> 6.9298072 | G6: =IFERROR(Tabela20[[#This Row],[GASTO TOTAL]]/Tabela20[[#This Row],[KM RODADO]],"-") -> 1.3533837 | H6: =IFERROR(Tabela20[[#This Row],[KM RODADO]]/Tabela20[[#This Row],[TOTAL DE LITROS]],"-") -> 5.1203568
A7: TKB0E17 | B7: GL-04 | C7: =IFERROR(VLOOKUP(Tabela20[[#This Row],[PLACA]],Resultados!$B$7:$H$121,3,0),"-") -> 35913 | D7: =IFERROR(VLOOKUP(Tabela20[[#This Row],[PLACA]],Resultados!$B$7:$H$121,4,0),"-") -> 8078.57 | E7: =IFERROR(VLOOKUP(Tabela20[[#This Row],[PLACA]],Resultados!$B$7:$H$121,5,0),"-") -> 50441.03 | F7: =IFERROR(E7/D7,"-") -> 6.2438068 | G7: =IFERROR(Tabela20[[#This Row],[GASTO TOTAL]]/Tabela20[[#This Row],[KM RODADO]],"-") -> 1.404534 | H7: =IFERROR(Tabela20[[#This Row],[KM RODADO]]/Tabela20[[#This Row],[TOTAL DE LITROS]],"-") -> 4.445465
A8: TJP1H27 | B8: GL-05 R | C8: =IFERROR(VLOOKUP(Tabela20[[#This Row],[PLACA]],Resultados!$B$7:$H$121,3,0),"-") -> 25090 | D8: =IFERROR(VLOOKUP(Tabela20[[#This Row],[PLACA]],Resultados!$B$7:$H$121,4,0),"-") -> 4686.25 | E8: =IFERROR(VLOOKUP(Tabela20[[#This Row],[PLACA]],Resultados!$B$7:$H$121,5,0),"-") -> 29913.05 | F8: =IFERROR(E8/D8,"-") -> 6.3831528 | G8: =IFERROR(Tabela20[[#This Row],[GASTO TOTAL]]/Tabela20[[#This Row],[KM RODADO]],"-") -> 1.19223 | H8: =IFERROR(Tabela20[[#This Row],[KM RODADO]]/Tabela20[[#This Row],[TOTAL DE LITROS]],"-") -> 5.3539611
A9: TKC7D89 | B9: GP-01 | C9: =IFERROR(VLOOKUP(Tabela20[[#This Row],[PLACA]],Resultados!$B$7:$H$121,3,0),"-") -> 35709 | D9: =IFERROR(VLOOKUP(Tabela20[[#This Row],[PLACA]],Resultados!$B$7:$H$121,4,0),"-") -> 15771.92 | E9: =IFERROR(VLOOKUP(Tabela20[[#This Row],[PLACA]],Resultados!$B$7:$H$121,5,0),"-") -> 113131.33 | F9: =IFERROR(E9/D9,"-") -> 7.1729587 | G9: =IFERROR(Tabela20[[#This Row],[GASTO TOTAL]]/Tabela20[[#This Row],[KM RODADO]],"-") -> 3.1681461 | H9: =IFERROR(Tabela20[[#This Row],[KM RODADO]]/Tabela20[[#This Row],[TOTAL DE LITROS]],"-") -> 2.2640871
A10: TKC9B59 | B10: GP-02 | C10: =IFERROR(VLOOKUP(Tabela20[[#This Row],[PLACA]],Resultados!$B$7:$H$121,3,0),"-") -> 13289 | D10: =IFERROR(VLOOKUP(Tabela20[[#This Row],[PLACA]],Resultados!$B$7:$H$121,4,0),"-") -> 7555.79 | E10: =IFERROR(VLOOKUP(Tabela20[[#This Row],[PLACA]],Resultados!$B$7:$H$121,5,0),"-") -> 54240.25 | F10: =IFERROR(E10/D10,"-") -> 7.1786339 | G10: =IFERROR(Tabela20[[#This Row],[GASTO TOTAL]]/Tabela20[[#This Row],[KM RODADO]],"-") -> 4.08159 | H10: =IFERROR(Tabela20[[#This Row],[KM RODADO]]/Tabela20[[#This Row],[TOTAL DE LITROS]],"-") -> 1.7587837
A11: TMG4A29 | B11: GP-03 | C11: =IFERROR(VLOOKUP(Tabela20[[#This Row],[PLACA]],Resultados!$B$7:$H$121,3,0),"-") -> 31779 | D11: =IFERROR(VLOOKUP(Tabela20[[#This Row],[PLACA]],Resultados!$B$7:$H$121,4,0),"-") -> 16791.28 | E11: =IFERROR(VLOOKUP(Tabela20[[#This Row],[PLACA]],Resultados!$B$7:$H$121,5,0),"-") -> 112390.05 | F11: =IFERROR(E11/D11,"-") -> 6.6933581 | G11: =IFERROR(Tabela20[[#This Row],[GASTO TOTAL]]/Tabela20[[#This Row],[KM RODADO]],"-") -> 3.5366138 | H11: =IFERROR(Tabela20[[#This Row],[KM RODADO]]/Tabela20[[#This Row],[TOTAL DE LITROS]],"-") -> 1.8925895
A12: TMF8H09 | B12: GP-04 R | C12: =IFERROR(VLOOKUP(Tabela20[[#This Row],[PLACA]],Resultados!$B$7:$H$121,3,0),"-") -> 19878 | D12: =IFERROR(VLOOKUP(Tabela20[[#This Row],[PLACA]],Resultados!$B$7:$H$121,4,0),"-") -> 10323.46 | E12: =IFERROR(VLOOKUP(Tabela20[[#This Row],[PLACA]],Resultados!$B$7:$H$121,5,0),"-") -> 71712.87 | F12: =IFERROR(E12/D12,"-") -> 6.9465925 | G12: =IFERROR(Tabela20[[#This Row],[GASTO TOTAL]]/Tabela20[[#This Row],[KM RODADO]],"-") -> 3.6076502 | H12: =IFERROR(Tabela20[[#This Row],[KM RODADO]]/Tabela20[[#This Row],[TOTAL DE LITROS]],"-") -> 1.9255172
D15: =SUBTOTAL(109,D3:D12) -> 95718.47 | E15: =SUBTOTAL(109,E3:E12) -> 644844.65 | G15: =SUBTOTAL(1,Tabela20[[#All],[CUSTO/KM]]) -> 2.2328409 | H15: =SUBTOTAL(1,Tabela20[MÉDIA]) -> 3.7874876
D17: Preço Médio Diesel = | E17: =E15/D15 -> 6.7368884

Sheet VA
A1: PAINEL DE RESULTADOS
A2: PLACA | B2: PRÉ-FIXO | C2: MOTORISTAS | D2: KM RODADO | E2: TOTAL DE LITROS | F2: GASTO TOTAL | G2: PREÇO MÉDIO | H2: CUSTO/KM | I2: MÉDIA
A3: TFX8A49 | B3: POOL-01 | C3: POOL | D3: =IFERROR(VLOOKUP(Tabela206[[#This Row],[PLACA]],Resultados!$B$7:$H$121,3,0),"-") -> 31113.031 | E3: =IFERROR(VLOOKUP(Tabela206[[#This Row],[PLACA]],Resultados!$B$7:$H$121,4,0),"-") -> 3337.5056 | F3: =IFERROR(VLOOKUP(Tabela206[[#This Row],[PLACA]],Resultados!$B$7:$H$121,5,0),"-") -> 15553.223 | G3: =IFERROR(F3/E3,"-") -> 4.6601338 | H3: =IFERROR(Tabela206[[#This Row],[GASTO TOTAL]]/Tabela206[[#This Row],[KM RODADO]],"-") -> 0.49989418 | I3: =IFERROR(Tabela206[[#This Row],[KM RODADO]]/Tabela206[[#This Row],[TOTAL DE LITROS]],"-") -> 9.3222407
A4: TFD2J89 | B4: POOL-02 | C4: POOL | D4: =IFERROR(VLOOKUP(Tabela206[[#This Row],[PLACA]],Resultados!$B$7:$H$121,3,0),"-") -> 32580.606 | E4: =IFERROR(VLOOKUP(Tabela206[[#This Row],[PLACA]],Resultados!$B$7:$H$121,4,0),"-") -> 3463.03 | F4: =IFERROR(VLOOKUP(Tabela206[[#This Row],[PLACA]],Resultados!$B$7:$H$121,5,0),"-") -> 16129.69 | G4: =IFERROR(F4/E4,"-") -> 4.6576813 | H4: =IFERROR(Tabela206[[#This Row],[GASTO TOTAL]]/Tabela206[[#This Row],[KM RODADO]],"-") -> 0.49507029 | I4: =IFERROR(Tabela206[[#This Row],[KM RODADO]]/Tabela206[[#This Row],[TOTAL DE LITROS]],"-") -> 9.4081212
A5: TFF6I82 | B5: POOL - 03 | C5: POOL | D5: =IFERROR(VLOOKUP(Tabela206[[#This Row],[PLACA]],Resultados!$B$7:$H$121,3,0),"-") -> 23654.443 | E5: =IFERROR(VLOOKUP(Tabela206[[#This Row],[PLACA]],Resultados!$B$7:$H$121,4,0),"-") -> 2413.0475 | F5: =IFERROR(VLOOKUP(Tabela206[[#This Row],[PLACA]],Resultados!$B$7:$H$121,5,0),"-") -> 10620.041 | G5: =IFERROR(F5/E5,"-") -> 4.4010907 | H5: =IFERROR(Tabela206[[#This Row],[GASTO TOTAL]]/Tabela206[[#This Row],[KM RODADO]],"-") -> 0.448966 | I5: =IFERROR(Tabela206[[#This Row],[KM RODADO]]/Tabela206[[#This Row],[TOTAL DE LITROS]],"-") -> 9.802726
A6: TGL4J09 | B6: VA-01 | C6: Jester | D6: =IFERROR(VLOOKUP(Tabela206[[#This Row],[PLACA]],Resultados!$B$7:$H$121,3,0),"-") -> 25413.003 | E6: =IFERROR(VLOOKUP(Tabela206[[#This Row],[PLACA]],Resultados!$B$7:$H$121,4,0),"-") -> 2844.2112 | F6: =IFERROR(VLOOKUP(Tabela206[[#This Row],[PLACA]],Resultados!$B$7:$H$121,5,0),"-") -> 13325.863 | G6: =IFERROR(F6/E6,"-") -> 4.6852578 | H6: =IFERROR(Tabela206[[#This Row],[GASTO TOTAL]]/Tabela206[[#This Row],[KM RODADO]],"-") -> 0.52437184 | I6: =IFERROR(Tabela206[[#This Row],[KM RODADO]]/Tabela206[[#This Row],[TOTAL DE LITROS]],"-") -> 8.9349913
A7: TFR8B59 | B7: VA-02 | C7: Dutra | D7: =IFERROR(VLOOKUP(Tabela206[[#This Row],[PLACA]],Resultados!$B$7:$H$121,3,0),"-") -> 30527.151 | E7: =IFERROR(VLOOKUP(Tabela206[[#This Row],[PLACA]],Resultados!$B$7:$H$121,4,0),"-") -> 3923.3235 | F7: =IFERROR(VLOOKUP(Tabela206[[#This Row],[PLACA]],Resultados!$B$7:$H$121,5,0),"-") -> 18199.161 | G7: =IFERROR(F7/E7,"-") -> 4.6387102 | H7: =IFERROR(Tabela206[[#This Row],[GASTO TOTAL]]/Tabela206[[#This Row],[KM RODADO]],"-") -> 0.59616308 | I7: =IFERROR(Tabela206[[#This Row],[KM RODADO]]/Tabela206[[#This Row],[TOTAL DE LITROS]],"-") -> 7.7809416
A8: TFI3B19 | B8: VA-03 | C8: Líderes | D8: =IFERROR(VLOOKUP(Tabela206[[#This Row],[PLACA]],Resultados!$B$7:$H$121,3,0),"-") -> 116144.21 | E8: =IFERROR(VLOOKUP(Tabela206[[#This Row],[PLACA]],Resultados!$B$7:$H$121,4,0),"-") -> 12053.305 | F8: =IFERROR(VLOOKUP(Tabela206[[#This Row],[PLACA]],Resultados!$B$7:$H$121,5,0),"-") -> 53627.69 | G8: =IFERROR(F8/E8,"-") -> 4.4492105 | H8: =IFERROR(Tabela206[[#This Row],[GASTO TOTAL]]/Tabela206[[#This Row],[KM RODADO]],"-") -> 0.46173366 | I8: =IFERROR(Tabela206[[#This Row],[KM RODADO]]/Tabela206[[#This Row],[TOTAL DE LITROS]],"-") -> 9.6358807
A9: TFY6E09 | B9: VA-04 | C9: Paulo Roberto | D9: =IFERROR(VLOOKUP(Tabela206[[#This Row],[PLACA]],Resultados!$B$7:$H$121,3,0),"-") -> 52099.446 | E9: =IFERROR(VLOOKUP(Tabela206[[#This Row],[PLACA]],Resultados!$B$7:$H$121,4,0),"-") -> 5288.1009 | F9: =IFERROR(VLOOKUP(Tabela206[[#This Row],[PLACA]],Resultados!$B$7:$H$121,5,0),"-") -> 23757.551 | G9: =IFERROR(F9/E9,"-") -> 4.4926433 | H9: =IFERROR(Tabela206[[#This Row],[GASTO TOTAL]]/Tabela206[[#This Row],[KM RODADO]],"-") -> 0.45600392 | I9: =IFERROR(Tabela206[[#This Row],[KM RODADO]]/Tabela206[[#This Row],[TOTAL DE LITROS]],"-") -> 9.8522033
A10: TFP3B22 | B10: VA-05 | C10: André - Cons | D10: =IFERROR(VLOOKUP(Tabela206[[#This Row],[PLACA]],Resultados!$B$7:$H$121,3,0),"-") -> 65592.737 | E10: =IFERROR(VLOOKUP(Tabela206[[#This Row],[PLACA]],Resultados!$B$7:$H$121,4,0),"-") -> 6896.3435 | F10: =IFERROR(VLOOKUP(Tabela206[[#This Row],[PLACA]],Resultados!$B$7:$H$121,5,0),"-") -> 31932.962 | G10: =IFERROR(F10/E10,"-") -> 4.6304194 | H10: =IFERROR(Tabela206[[#This Row],[GASTO TOTAL]]/Tabela206[[#This Row],[KM RODADO]],"-") -> 0.48683686 | I10: =IFERROR(Tabela206[[#This Row],[KM RODADO]]/Tabela206[[#This Row],[TOTAL DE LITROS]],"-") -> 9.5112341
A11: TFS3C72 | B11: VA-06 | C11: Heder | D11: =IFERROR(VLOOKUP(Tabela206[[#This Row],[PLACA]],Resultados!$B$7:$H$121,3,0),"-") -> 98627.209 | E11: =IFERROR(VLOOKUP(Tabela206[[#This Row],[PLACA]],Resultados!$B$7:$H$121,4,0),"-") -> 12300.155 | F11: =IFERROR(VLOOKUP(Tabela206[[#This Row],[PLACA]],Resultados!$B$7:$H$121,5,0),"-") -> 55914.271 | G11: =IFERROR(F11/E11,"-") -> 4.5458184 | H11: =IFERROR(Tabela206[[#This Row],[GASTO TOTAL]]/Tabela206[[#This Row],[KM RODADO]],"-") -> 0.56692541 | I11: =IFERROR(Tabela206[[#This Row],[KM RODADO]]/Tabela206[[#This Row],[TOTAL DE LITROS]],"-") -> 8.0183713
A12: TFN0D12 | B12: VA-07 | C12: Silvino | D12: =IFERROR(VLOOKUP(Tabela206[[#This Row],[PLACA]],Resultados!$B$7:$H$121,3,0),"-") -> 53850.955 | E12: =IFERROR(VLOOKUP(Tabela206[[#This Row],[PLACA]],Resultados!$B$7:$H$121,4,0),"-") -> 5763.1531 | F12: =IFERROR(VLOOKUP(Tabela206[[#This Row],[PLACA]],Resultados!$B$7:$H$121,5,0),"-") -> 26576.254 | G12: =IFERROR(F12/E12,"-") -> 4.6114086 | H12: =IFERROR(Tabela206[[#This Row],[GASTO TOTAL]]/Tabela206[[#This Row],[KM RODADO]],"-") -> 0.49351499 | I12: =IFERROR(Tabela206[[#This Row],[KM RODADO]]/Tabela206[[#This Row],[TOTAL DE LITROS]],"-") -> 9.3440092
A13: TFX7J72 | B13: VA-08 | C13: Pedro | D13: =IFERROR(VLOOKUP(Tabela206[[#This Row],[PLACA]],Resultados!$B$7:$H$121,3,0),"-") -> 79386.385 | E13: =IFERROR(VLOOKUP(Tabela206[[#This Row],[PLACA]],Resultados!$B$7:$H$121,4,0),"-") -> 9045.8612 | F13: =IFERROR(VLOOKUP(Tabela206[[#This Row],[PLACA]],Resultados!$B$7:$H$121,5,0),"-") -> 40929.84 | G13: =IFERROR(F13/E13,"-") -> 4.5247035 | H13: =IFERROR(Tabela206[[#This Row],[GASTO TOTAL]]/Tabela206[[#This Row],[KM RODADO]],"-") -> 0.51557758 | I13: =IFERROR(Tabela206[[#This Row],[KM RODADO]]/Tabela206[[#This Row],[TOTAL DE LITROS]],"-") -> 8.7759897
A14: PQL3980 | B14: VA - 09 R | C14: Weider | D14: =IFERROR(VLOOKUP(Tabela206[[#This Row],[PLACA]],Resultados!$B$7:$H$121,3,0),"-") -> 5569 | E14: =IFERROR(VLOOKUP(Tabela206[[#This Row],[PLACA]],Resultados!$B$7:$H$121,4,0),"-") -> 579.86 | F14: =IFERROR(VLOOKUP(Tabela206[[#This Row],[PLACA]],Resultados!$B$7:$H$121,5,0),"-") -> 2838.84 | G14: =IFERROR(F14/E14,"-") -> 4.8957335 | H14: =IFERROR(Tabela206[[#This Row],[GASTO TOTAL]]/Tabela206[[#This Row],[KM RODADO]],"-") -> 0.50975759 | I14: =IFERROR(Tabela206[[#This Row],[KM RODADO]]/Tabela206[[#This Row],[TOTAL DE LITROS]],"-") -> 9.6040424
... A25: TFZ6A74 | B25: MP-01 | C25: Marcus | D25: =IFERROR(VLOOKUP(Tabela206[[#This Row],[PLACA]],Resultados!$B$7:$H$121,3,0),"-") -> 2330 | E25: =IFERROR(VLOOKUP(Tabela206[[#This Row],[PLACA]],Resultados!$B$7:$H$121,4,0),"-") -> 284.37 | F25: =IFERROR(VLOOKUP(Tabela206[[#This Row],[PLACA]],Resultados!$B$7:$H$121,5,0),"-") -> 1358.96 | G25: =IFERROR(F25/E25,"-") -> 4.7788445 | H25: =IFERROR(Tabela206[[#This Row],[GASTO TOTAL]]/Tabela206[[#This Row],[KM RODADO]],"-") -> 0.58324464 | I25: =IFERROR(Tabela206[[#This Row],[KM RODADO]]/Tabela206[[#This Row],[TOTAL DE LITROS]],"-") -> 8.1935507
C28: TOTAL | E28: =SUBTOTAL(109,E16:E25) -> 32903.757 | F28: =SUBTOTAL(109,F3:F25) -> 488164.18 | H28: =SUBTOTAL(1,Tabela206[[#All],[CUSTO/KM]]) -> 0.51415297 | I28: =SUBTOTAL(1,Tabela206[MÉDIA]) -> 9.0802637
E30: Preço Médio Etanol = | F30: =F28/E28 -> 14.836122

Sheet TI
A1: PAINEL DE RESULTADOS
A2: PLACA | B2: PRÉ-FIXO | C2: KM RODADO | D2: TOTAL DE LITROS | E2: GASTO TOTAL | F2: PREÇO MÉDIO | G2: CUSTO/KM | H2: MÉDIA
A3: TGM2I26 | B3: TI-01 | C3: =IFERROR(VLOOKUP(Tabela207[[#This Row],[PLACA]],Resultados!$B$7:$H$121,3,0),"-") -> 30507 | D3: =IFERROR(VLOOKUP(Tabela207[[#This Row],[PLACA]],Resultados!$B$7:$H$121,4,0),"-") -> 3771.42 | E3: =IFERROR(VLOOKUP(Tabela207[[#This Row],[PLACA]],Resultados!$B$7:$H$121,5,0),"-") -> 18130.5 | F3: =IFERROR(Tabela207[[#This Row],[GASTO TOTAL]]/Tabela207[[#This Row],[KM RODADO]],"-") -> 0.59430622 | G3: =IFERROR(Tabela207[[#This Row],[KM RODADO]]/Tabela207[[#This Row],[GASTO TOTAL]],"-") -> 1.6826342 | H3: =IFERROR(Tabela207[[#This Row],[KM RODADO]]/Tabela207[[#This Row],[TOTAL DE LITROS]],"-") -> 8.0889957
A4: TGK2G46 | B4: TI-02 | C4: =IFERROR(VLOOKUP(Tabela207[[#This Row],[PLACA]],Resultados!$B$7:$H$121,3,0),"-") -> 30680 | D4: =IFERROR(VLOOKUP(Tabela207[[#This Row],[PLACA]],Resultados!$B$7:$H$121,4,0),"-") -> 4810.76 | E4: =IFERROR(VLOOKUP(Tabela207[[#This Row],[PLACA]],Resultados!$B$7:$H$121,5,0),"-") -> 23351.57 | F4: =IFERROR(Tabela207[[#This Row],[GASTO TOTAL]]/Tabela207[[#This Row],[KM RODADO]],"-") -> 0.76113331 | G4: =IFERROR(Tabela207[[#This Row],[KM RODADO]]/Tabela207[[#This Row],[GASTO TOTAL]],"-") -> 1.3138303 | H4: =IFERROR(Tabela207[[#This Row],[KM RODADO]]/Tabela207[[#This Row],[TOTAL DE LITROS]],"-") -> 6.3773707
A5: TGA0B06 | B5: TI-03 | C5: =IFERROR(VLOOKUP(Tabela207[[#This Row],[PLACA]],Resultados!$B$7:$H$121,3,0),"-") -> 25701 | D5: =IFERROR(VLOOKUP(Tabela207[[#This Row],[PLACA]],Resultados!$B$7:$H$121,4,0),"-") -> 3257.13 | E5: =IFERROR(VLOOKUP(Tabela207[[#This Row],[PLACA]],Resultados!$B$7:$H$121,5,0),"-") -> 15859.65 | F5: =IFERROR(Tabela207[[#This Row],[GASTO TOTAL]]/Tabela207[[#This Row],[KM RODADO]],"-") -> 0.61708299 | G5: =IFERROR(Tabela207[[#This Row],[KM RODADO]]/Tabela207[[#This Row],[GASTO TOTAL]],"-") -> 1.6205276 | H5: =IFERROR(Tabela207[[#This Row],[KM RODADO]]/Tabela207[[#This Row],[TOTAL DE LITROS]],"-") -> 7.890689
A6: TGM4D76 | B6: TI-04 | C6: =IFERROR(VLOOKUP(Tabela207[[#This Row],[PLACA]],Resultados!$B$7:$H$121,3,0),"-") -> 36151 | D6: =IFERROR(VLOOKUP(Tabela207[[#This Row],[PLACA]],Resultados!$B$7:$H$121,4,0),"-") -> 4555.89 | E6: =IFERROR(VLOOKUP(Tabela207[[#This Row],[PLACA]],Resultados!$B$7:$H$121,5,0),"-") -> 21668.83 | F6: =IFERROR(Tabela207[[#This Row],[GASTO TOTAL]]/Tabela207[[#This Row],[KM RODADO]],"-") -> 0.5993978 | G6: =IFERROR(Tabela207[[#This Row],[KM RODADO]]/Tabela207[[#This Row],[GASTO TOTAL]],"-") -> 1.6683411 | H6: =IFERROR(Tabela207[[#This Row],[KM RODADO]]/Tabela207[[#This Row],[TOTAL DE LITROS]],"-") -> 7.9350028
A7: RBP0A22 | B7: TI-05 | C7: =IFERROR(VLOOKUP(Tabela207[[#This Row],[PLACA]],Resultados!$B$7:$H$121,3,0),"-") -> 16396 | D7: =IFERROR(VLOOKUP(Tabela207[[#This Row],[PLACA]],Resultados!$B$7:$H$121,4,0),"-") -> 1933.02 | E7: =IFERROR(VLOOKUP(Tabela207[[#This Row],[PLACA]],Resultados!$B$7:$H$121,5,0),"-") -> 9292.66 | F7: =IFERROR(Tabela207[[#This Row],[GASTO TOTAL]]/Tabela207[[#This Row],[KM RODADO]],"-") -> 0.56676384 | G7: =IFERROR(Tabela207[[#This Row],[KM RODADO]]/Tabela207[[#This Row],[GASTO TOTAL]],"-") -> 1.7644033 | H7: =IFERROR(Tabela207[[#This Row],[KM RODADO]]/Tabela207[[#This Row],[TOTAL DE LITROS]],"-") -> 8.4820643
A8: RCJ8I11 | B8: TI-06 | C8: =IFERROR(VLOOKUP(Tabela207[[#This Row],[PLACA]],Resultados!$B$7:$H$121,3,0),"-") -> 10914 | D8: =IFERROR(VLOOKUP(Tabela207[[#This Row],[PLACA]],Resultados!$B$7:$H$121,4,0),"-") -> 1070.52 | E8: =IFERROR(VLOOKUP(Tabela207[[#This Row],[PLACA]],Resultados!$B$7:$H$121,5,0),"-") -> 5268.54 | F8: =IFERROR(Tabela207[[#This Row],[GASTO TOTAL]]/Tabela207[[#This Row],[KM RODADO]],"-") -> 0.48273227 | G8: =IFERROR(Tabela207[[#This Row],[KM RODADO]]/Tabela207[[#This Row],[GASTO TOTAL]],"-") -> 2.0715416 | H8: =IFERROR(Tabela207[[#This Row],[KM RODADO]]/Tabela207[[#This Row],[TOTAL DE LITROS]],"-") -> 10.195045
B13: TOTAL | D13: =SUBTOTAL(109,D3:D9) -> 19398.74 | E13: =SUBTOTAL(109,E3:E10) -> 93571.75 | G13: =SUBTOTAL(1,Tabela207[[#All],[CUSTO/KM]]) -> 1.6868797 | H13: =SUBTOTAL(1,Tabela207[MÉDIA]) -> 8.161528
D15: Preço Médio Diesel = | E15: =E13/D13 -> 4.8235994

Sheet Resultados
C3: Ano | D3: (Tudo)
C4: Mês | D4: (Tudo)
C5: ÁREA | D5: (Tudo)
B7: Placa | C7: Viaturas | D7: Distância | E7: Litros | F7: Valor abastecido | G7: Média
B8: =_xlfn.XLOOKUP(C8,Combustivel!F:F,Combustivel!A:A) -> TFV8C74 | C8: A-01 | D8: 19232 | E8: 3505.55 | F8: 23526.06 | G8: 5.5240845
B9: =_xlfn.XLOOKUP(C9,Combustivel!F:F,Combustivel!A:A) -> TFM4H34 | C9: A-02 | D9: 14412 | E9: 2465.43 | F9: 16410.42 | G9: 5.972
B10: =_xlfn.XLOOKUP(C10,Combustivel!F:F,Combustivel!A:A) -> TFB0B52 | C10: ANTT-02 | D10: 0 | E10: 133.44 | F10: 862.4 | G10: 0
B11: =_xlfn.XLOOKUP(C11,Combustivel!F:F,Combustivel!A:A) -> QSW6J59 | C11: CP - 01 | D11: 33304 | E11: 8783.62 | F11: 56791.66 | G11: 4.1773494
B12: =_xlfn.XLOOKUP(C12,Combustivel!F:F,Combustivel!A:A) -> TIV6G27 | C12: GL - 01 | D12: 49256 | E12: 8494.43 | F12: 54928.3 | G12: 6.0957447
B13: =_xlfn.XLOOKUP(C13,Combustivel!F:F,Combustivel!A:A) -> TLO0E87 | C13: GL - 02 | D13: 47060 | E13: 8519.36 | F13: 54770.84 | G13: 6.2819847
B14: =_xlfn.XLOOKUP(C14,Combustivel!F:F,Combustivel!A:A) -> TJE5D27 | C14: GL - 03 | D14: 34377 | E14: 6713.79 | F14: 46525.27 | G14: 5.3782051
B15: =_xlfn.XLOOKUP(C15,Combustivel!F:F,Combustivel!A:A) -> TKB0E17 | C15: GL - 04 | D15: 35913 | E15: 8078.57 | F15: 50441.03 | G15: 5.061978
B16: =_xlfn.XLOOKUP(C16,Combustivel!F:F,Combustivel!A:A) -> TJP1H27 | C16: GL - 05 Reserva | D16: 25090 | E16: 4686.25 | F16: 29913.05 | G16: 5.7120896
B17: =_xlfn.XLOOKUP(C17,Combustivel!F:F,Combustivel!A:A) -> TKC7D89 | C17: GP - 01 | D17: 35709 | E17: 15771.92 | F17: 113131.33 | G17: 2.5096667
B18: =_xlfn.XLOOKUP(C18,Combustivel!F:F,Combustivel!A:A) -> TKC9B59 | C18: GP - 02 | D18: 13289 | E18: 7555.79 | F18: 54240.25 | G18: 1.9970588
B19: =_xlfn.XLOOKUP(C19,Combustivel!F:F,Combustivel!A:A) -> TMG4A29 | C19: GP - 03 | D19: 31779 | E19: 16791.28 | F19: 112390.05 | G19: 2.1196552
... B87: =_xlfn.XLOOKUP(C87,Combustivel!F:F,Combustivel!A:A) -> TUK2D26 | C87: VIA-12-R | D87: 99085 | E87: 7310.91 | F87: 44741.68 | G87: 13.557557
B88: =_xlfn.XLOOKUP(C88,Combustivel!F:F,Combustivel!A:A) -> #N/A | C88: (vazio)
B89: =_xlfn.XLOOKUP(C89,Combustivel!F:F,Combustivel!A:A) -> #N/A | C89: Total Geral | D89: 3457095.5 | E89: 512755.91 | F89: 2855434.7 | G89: 7.8955513

Sheet Combustivel
A1: PLACA | B1: NUMERO CARTAO | C1: DATA | D1: MATRICULA | E1: MOTORISTA | F1: NUMERO FROTA | G1: TIPO FROTA | H1: MODELO | I1: FABRICANTE | J1: TERMINAL | K1: ESTABELECIMENTO | L1: CIDADE | M1: UF | N1: PRODUTO | O1: DISTANCIA | P1: CONSUMO | Q1: UNIDADE | R1: HODOMETRO | S1: QUANTIDADE | T1: VALOR UNITARIO | U1: VALOR TOTAL | V1: CUPOM FISCAL | W1: CENTRO RESULTADO | X1: FILIAL | Y1: CENTRO CUSTO | Z1: NUMERO TAG NFC | AA1: aux data | AB1: Aux Mês | AC1: Aux Ano | AD1: ÁREA
A2: TFD2J89 | B2: Reembolso | C2: 45748 | D2: n/a | E2: EDUARDO DE SOUSA PIMENTEL | F2: POOL - 02 | G2: Automóvel | H2: ARGO | I2: FIAT | J2: n/a | K2: n/a | L2: n/a | M2: GO | N2: ETANOL COMUM | O2: 0 | P2: =P51 -> 10.83 | Q2: Km/L | R2: 0 | S2: 0 | T2: 4.59 | U2: =S2*T2 -> 0 | V2: 0 | W2: Planejamento Operaci | X2: Planejamento Operaci | Y2: Operacional | AA2: 45748 | AB2: =MONTH(AA2) -> 4 | AC2: =YEAR(AA2) -> 2025 | AD2: =IFERROR(VLOOKUP(A2,'Aux Área'!$A$4:$B$123,2,0),"-") -> OPERAÇÃO
A3: TFE6B22 | B3: Reembolso | C3: 45748 | D3: n/a | E3: EDUARDO DE SOUSA PIMENTEL | F3: VA - 09 | G3: Automóvel | H3: ARGO | I3: FIAT | J3: n/a | K3: n/a | L3: n/a | M3: GO | N3: ETANOL COMUM | O3: =R17-O17 -> 0 | P3: =P17 -> 8.69 | Q3: Km/L | R3: =O3 -> 0 | S3: =O3/P3 -> 0 | T3: 4.59 | U3: =S3*T3 -> 0 | V3: 0 | W3: Planejamento Operaci | X3: Planejamento Operaci | Y3: Operacional | AA3: 45748 | AB3: =MONTH(AA3) -> 4 | AC3: =YEAR(AA3) -> 2025 | AD3: =IFERROR(VLOOKUP(A3,'Aux Área'!$A$4:$B$123,2,0),"-") -> ENGENHARIA
A4: TFF5D72 | B4: Reembolso | C4: 45748 | D4: n/a | E4: EDUARDO DE SOUSA PIMENTEL | F4: VA - 11 | G4: Automóvel | H4: ARGO | I4: FIAT | J4: n/a | K4: n/a | L4: n/a | M4: GO | N4: ETANOL COMUM | O4: =R9-O9 -> 0 | P4: 7.47 | Q4: Km/L | R4: =O4 -> 0 | S4: =O4/P4 -> 0 | T4: 4.59 | U4: =S4*T4 -> 0 | V4: 0 | W4: Planejamento Operaci | X4: Planejamento Operaci | Y4: Operacional | AA4: 45748 | AB4: =MONTH(AA4) -> 4 | AC4: =YEAR(AA4) -> 2025 | AD4: =IFERROR(VLOOKUP(A4,'Aux Área'!$A$4:$B$123,2,0),"-") -> OPERAÇÃO
A5: TFF6I82 | B5: Reembolso | C5: 45748 | D5: n/a | E5: EDUARDO DE SOUSA PIMENTEL | F5: POOL - 03 | G5: Automóvel | H5: ARGO | I5: FIAT | J5: n/a | K5: n/a | L5: n/a | M5: GO | N5: ETANOL COMUM | O5: =R158-O158 -> 4490 | P5: =P158 -> 11.06 | Q5: Km/L | R5: =O5 -> 4490 | S5: =O5/P5 -> 405.96745 | T5: 4.59 | U5: =S5*T5 -> 1863.3906 | V5: 0 | W5: Planejamento Operaci | X5: Planejamento Operaci | Y5: Operacional | AA5: 45748 | AB5: =MONTH(AA5) -> 4 | AC5: =YEAR(AA5) -> 2025 | AD5: =IFERROR(VLOOKUP(A5,'Aux Área'!$A$4:$B$123,2,0),"-") -> FACILITIES
A6: TFI3B19 | B6: Reembolso | C6: 45748 | D6: n/a | E6: EDUARDO DE SOUSA PIMENTEL | F6: VA - 03 | G6: Automóvel | H6: ARGO | I6: FIAT | J6: n/a | K6: n/a | L6: n/a | M6: GO | N6: ETANOL COMUM | O6: =R123-O123 -> 6305 | P6: =P123 -> 8.5 | Q6: Km/L | R6: =O6 -> 6305 | S6: =O6/P6 -> 741.76471 | T6: 4.59 | U6: =S6*T6 -> 3404.7 | V6: 0 | W6: Planejamento Operaci | X6: Planejamento Operaci | Y6: Operacional | AA6: 45748 | AB6: =MONTH(AA6) -> 4 | AC6: =YEAR(AA6) -> 2025 | AD6: =IFERROR(VLOOKUP(A6,'Aux Área'!$A$4:$B$123,2,0),"-") -> OPERAÇÃO
A7: TFN0D12 | B7: Reembolso | C7: 45748 | D7: n/a | E7: EDUARDO DE SOUSA PIMENTEL | F7: VA - 07 | G7: Automóvel | H7: ARGO | I7: FIAT | J7: n/a | K7: n/a | L7: n/a | M7: GO | N7: ETANOL COMUM | O7: =R245-O245 -> 6181 | P7: 7.47 | Q7: Km/L | R7: =O7 -> 6181 | S7: =O7/P7 -> 827.44311 | T7: 4.59 | U7: =S7*T7 -> 3797.9639 | V7: 0 | W7: Planejamento Operaci | X7: Planejamento Operaci | Y7: Operacional | AA7: 45748 | AB7: =MONTH(AA7) -> 4 | AC7: =YEAR(AA7) -> 2025 | AD7: =IFERROR(VLOOKUP(A7,'Aux Área'!$A$4:$B$123,2,0),"-") -> QSMS
A8: TFP3B22 | B8: Reembolso | C8: 45748 | D8: n/a | E8: EDUARDO DE SOUSA PIMENTEL | F8: VA - 05 | G8: Automóvel | H8: ARGO | I8: FIAT | J8: n/a | K8: n/a | L8: n/a | M8: GO | N8: ETANOL COMUM | O8: =R25-O25 -> 368.9604 | P8: =P25 -> 9.62 | Q8: Km/L | R8: =O8 -> 368.9604 | S8: =O8/P8 -> 38.353472 | T8: 4.59 | U8: =S8*T8 -> 176.04244 | V8: 0 | W8: Planejamento Operaci | X8: Planejamento Operaci | Y8: Operacional | AA8: 45748 | AB8: =MONTH(AA8) -> 4 | AC8: =YEAR(AA8) -> 2025 | AD8: =IFERROR(VLOOKUP(A8,'Aux Área'!$A$4:$B$123,2,0),"-") -> CONSERVA
A9: TFP9I32 | B9: Reembolso | C9: 45748 | D9: n/a | E9: EDUARDO DE SOUSA PIMENTEL | F9: VA - 13 | G9: Automóvel | H9: ARGO | I9: FIAT | J9: n/a | K9: n/a | L9: n/a | M9: GO | N9: ETANOL COMUM | O9: =R14-O14 -> 0 | P9: 7.47 | Q9: Km/L | R9: =O9 -> 0 | S9: =O9/P9 -> 0 | T9: 4.59 | U9: =S9*T9 -> 0 | V9: 0 | W9: Planejamento Operaci | X9: Planejamento Operaci | Y9: Operacional | AA9: 45748 | AB9: =MONTH(AA9) -> 4 | AC9: =YEAR(AA9) -> 2025 | AD9: =IFERROR(VLOOKUP(A9,'Aux Área'!$A$4:$B$123,2,0),"-") -> CONSERVA
A10: TFR8B59 | B10: Reembolso | C10: 45748 | D10: n/a | E10: EDUARDO DE SOUSA PIMENTEL | F10: VA - 02 | G10: Automóvel | H10: ARGO | I10: FIAT | J10: n/a | K10: n/a | L10: n/a | M10: GO | N10: ETANOL COMUM | O10: =R50-O50 -> 3055 | P10: =P50 -> 8.69 | Q10: Km/L | R10: =O10 -> 3055 | S10: =O10/P10 -> 351.55351 | T10: 4.59 | U10: =S10*T10 -> 1613.6306 | V10: 0 | W10: Planejamento Operaci | X10: Planejamento Operaci | Y10: Operacional | AA10: 45748 | AB10: =MONTH(AA10) -> 4 | AC10: =YEAR(AA10) -> 2025 | AD10: =IFERROR(VLOOKUP(A10,'Aux Área'!$A$4:$B$123,2,0),"-") -> TI
A11: TFS3C72 | B11: Reembolso | C11: 45748 | D11: n/a | E11: EDUARDO DE SOUSA PIMENTEL | F11: VA - 06 | G11: Automóvel | H11: ARGO | I11: FIAT | J11: n/a | K11: n/a | L11: n/a | M11: GO | N11: ETANOL COMUM | O11: =R22-O22 -> 402.324 | P11: =P22 -> 8.9 | Q11: Km/L | R11: =O11 -> 402.324 | S11: =O11/P11 -> 45.204944 | T11: 4.59 | U11: =S11*T11 -> 207.49069 | V11: 0 | W11: Planejamento Operaci | X11: Planejamento Operaci | Y11: Operacional | AA11: 45748 | AB11: =MONTH(AA11) -> 4 | AC11: =YEAR(AA11) -> 2025 | AD11: =IFERROR(VLOOKUP(A11,'Aux Área'!$A$4:$B$123,2,0),"-") -> CONSERVA
A12: TFW2H32 | B12: Reembolso | C12: 45748 | D12: n/a | E12: EDUARDO DE SOUSA PIMENTEL | F12: VA - 15 | G12: Automóvel | H12: ARGO | I12: FIAT | J12: n/a | K12: n/a | L12: n/a | M12: GO | N12: ETANOL COMUM | O12: =R113-O113 -> 7635 | P12: 7.47 | Q12: Km/L | R12: =O12 -> 7635 | S12: =O12/P12 -> 1022.0884 | T12: 4.59 | U12: =S12*T12 -> 4691.3855 | V12: 0 | W12: Planejamento Operaci | X12: Planejamento Operaci | Y12: Operacional | AA12: 45748 | AB12: =MONTH(AA12) -> 4 | AC12: =YEAR(AA12) -> 2025 | AD12: =IFERROR(VLOOKUP(A12,'Aux Área'!$A$4:$B$123,2,0),"-") -> QSMS
A13: TFX7J72 | B13: Reembolso | C13: 45748 | D13: n/a | E13: EDUARDO DE SOUSA PIMENTEL | F13: VA - 08 | G13: Automóvel | H13: ARGO | I13: FIAT | J13: n/a | K13: n/a | L13: n/a | M13: GO | N13: ETANOL COMUM | O13: =R33-O33 -> 2456 | P13: =P33 -> 8.5 | Q13: Km/L | R13: =O13 -> 2456 | S13: =O13/P13 -> 288.94118 | T13: 4.59 | U13: =S13*T13 -> 1326.24 | V13: 0 | W13: Planejamento Operaci | X13: Planejamento Operaci | Y13: Operacional | AA13: 45748 | AB13: =MONTH(AA13) -> 4 | AC13: =YEAR(AA13) -> 2025 | AD13: =IFERROR(VLOOKUP(A13,'Aux Área'!$A$4:$B$123,2,0),"-") -> CONSERVA
A14: TFX8A49 | B14: Reembolso | C14: 45748 | D14: n/a | E14: EDUARDO DE SOUSA PIMENTEL | F14: POOL - 01 | G14: Automóvel | H14: ARGO | I14: FIAT | J14: n/a | K14: n/a | L14: n/a | M14: GO | N14: ETANOL COMUM | O14: =R51-O51 -> 4801 | P14: =P51 -> 10.83 | Q14: Km/L | R14: =O14 -> 4801 | S14: =O14/P14 -> 443.30563 | T14: 4.59 | U14: =S14*T14 -> 2034.7729 | V14: 0 | W14: Planejamento Operaci | X14: Planejamento Operaci | Y14: Operacional | AA14: 45748 | AB14: =MONTH(AA14) -> 4 | AC14: =YEAR(AA14) -> 2025 | AD14: =IFERROR(VLOOKUP(A14,'Aux Área'!$A$4:$B$123,2,0),"-") -> OPERAÇÃO
A15: TFY2H52 | B15: Reembolso | C15: 45748 | D15: n/a | E15: EDUARDO DE SOUSA PIMENTEL | F15: VA - 12 | G15: Automóvel | H15: ARGO | I15: FIAT | J15: n/a | K15: n/a | L15: n/a | M15: GO | N15: ETANOL COMUM | O15: =R29-O29 -> 2610 | P15: 7.47 | Q15: Km/L | R15: =O15 -> 2610 | S15: =O15/P15 -> 349.39759 | T15: 4.59 | U15: =S15*T15 -> 1603.7349 | V15: 0 | W15: Planejamento Operaci | X15: Planejamento Operaci | Y15: Operacional | AA15: 45748 | AB15: =MONTH(AA15) -> 4 | AC15: =YEAR(AA15) -> 2025 | AD15: =IFERROR(VLOOKUP(A15,'Aux Área'!$A$4:$B$123,2,0),"-") -> QSMS
A16: TFY3C02 | B16: Reembolso | C16: 45748 | D16: n/a | E16: EDUARDO DE SOUSA PIMENTEL | F16: VA - 10 | G16: Automóvel | H16: ARGO | I16: FIAT | J16: n/a | K16: n/a | L16: n/a | M16: GO | N16: ETANOL COMUM | O16: =R33-O33 -> 2456 | P16: 7.47 | Q16: Km/L | R16: =O16 -> 2456 | S16: =O16/P16 -> 328.78179 | T16: 4.59 | U16: =S16*T16 -> 1509.1084 | V16: 0 | W16: Planejamento Operaci | X16: Planejamento Operaci | Y16: Operacional | AA16: 45748 | AB16: =MONTH(AA16) -> 4 | AC16: =YEAR(AA16) -> 2025 | AD16: =IFERROR(VLOOKUP(A16,'Aux Área'!$A$4:$B$123,2,0),"-") -> OPERAÇÃO
A17: TFY6E09 | B17: Reembolso | C17: 45748 | D17: n/a | E17: EDUARDO DE SOUSA PIMENTEL | F17: VA - 04 | G17: Automóvel | H17: ARGO | I17: FIAT | J17: n/a | K17: n/a | L17: n/a | M17: GO | N17: ETANOL COMUM | O17: =R32-O32 -> 2609.6152 | P17: =P32 -> 8.69 | Q17: Km/L | R17: =O17 -> 2609.6152 | S17: =O17/P17 -> 300.30094 | T17: 4.59 | U17: =S17*T17 -> 1378.3813 | V17: 0 | W17: Planejamento Operaci | X17: Planejamento Operaci | Y17: Operacional | AA17: 45748 | AB17: =MONTH(AA17) -> 4 | AC17: =YEAR(AA17) -> 2025 | AD17: =IFERROR(VLOOKUP(A17,'Aux Área'!$A$4:$B$123,2,0),"-") -> ENGENHARIA
A18: TGF2J32 | B18: Reembolso | C18: 45748 | D18: n/a | E18: EDUARDO DE SOUSA PIMENTEL | F18: VA - 14 | G18: Automóvel | H18: ARGO | I18: FIAT | J18: n/a | K18: n/a | L18: n/a | M18: GO | N18: ETANOL COMUM | O18: =R25-O25 -> 368.9604 | P18: 7.47 | Q18: Km/L | R18: =O18 -> 368.9604 | S18: =O18/P18 -> 49.392289 | T18: 4.59 | U18: =S18*T18 -> 226.71061 | V18: 0 | W18: Planejamento Operaci | X18: Planejamento Operaci | Y18: Operacional | AA18: 45748 | AB18: =MONTH(AA18) -> 4 | AC18: =YEAR(AA18) -> 2025 | AD18: =IFERROR(VLOOKUP(A18,'Aux Área'!$A$4:$B$123,2,0),"-") -> TI
A19: TGL4J09 | B19: Reembolso | C19: 45748 | D19: n/a | E19: EDUARDO DE SOUSA PIMENTEL | F19: VA - 01 | G19: Automóvel | H19: ARGO | I19: FIAT | J19: n/a | K19: n/a | L19: n/a | M19: GO | N19: ETANOL COMUM | O19: =R42-O42 -> 1378 | P19: 7.47 | Q19: Km/L | R19: =O19 -> 1378 | S19: =O19/P19 -> 184.47122 | T19: 4.59 | U19: =S19*T19 -> 846.72289 | V19: 0 | W19: Planejamento Operaci | X19: Planejamento Operaci | Y19: Operacional | AA19: 45748 | AB19: =MONTH(AA19) -> 4 | AC19: =YEAR(AA19) -> 2025 | AD19: =IFERROR(VLOOKUP(A19,'Aux Área'!$A$4:$B$123,2,0),"-") -> ENGENHARIA
A20: TFF5D72 | B20: 60645800105124274 | C20: 12/05/2025 14:36:33 | D20: 26270 | E20: CRISTIANO TORRES WARDIL | F20: VA - 11 | G20: Automóvel | H20: ARGO | I20: FIAT | J20: 92267803 | K20: POSTO XANDAO | L20: GOIANIA | M20: GO | N20: ETANOL COMUM | O20: =P20*S20 -> 178.4887 | P20: =P258 -> 5.59 | Q20: Km/L | R20: 184 | S20: 31.93 | T20: 4.84 | U20: 154.54 | V20: 0 | W20: Planejamento Operaci | X20: Planejamento Operaci | Y20: Operacional | AA20: =DATEVALUE(C20) -> 45789 | AB20: =MONTH(AA20) -> 5 | AC20: =YEAR(AA20) -> 2025 | AD20: =IFERROR(VLOOKUP(A20,'Aux Área'!$A$4:$B$123,2,0),"-") -> OPERAÇÃO
A21: TFS3C72 | B21: 60645800105124220 | C21: 12/05/2025 17:26:45 | D21: 00271 | E21: HEDER OLIVEIRA SANTANA | F21: VA - 06 | G21: Automóvel | H21: ARGO | I21: FIAT | J21: 07674909 | K21: AUTO POSTO INDIARA | L21: INDIARA | M21: GO | N21: ETANOL COMUM | O21: =P21*S21 -> 340.885 | P21: =P24 -> 8.63 | Q21: Km/L | R21: 2108 | S21: 39.5 | T21: 4.55 | U21: 179.72 | V21: 5228 | W21: Planejamento Operaci | X21: Planejamento Operaci | Y21: Operacional | AA21: =DATEVALUE(C21) -> 45789 | AB21: =MONTH(AA21) -> 5 | AC21: =YEAR(AA21) -> 2025 | AD21: =IFERROR(VLOOKUP(A21,'Aux Área'!$A$4:$B$123,2,0),"-") -> CONSERVA
A22: TFP9I32 | B22: 60645800105124300 | C22: 12/05/2025 18:51:13 | D22: 33861 | E22: FERNANDO DOS REIS GONÇALVES | F22: VA - 13 | G22: Automóvel | H22: ARGO | I22: FIAT | J22: 26466212 | K22: AUTO POSTO GLOBAL AR | L22: GOIANIA | M22: GO | N22: ETANOL COMUM | O22: =P22*S22 -> 345.676 | P22: =P36 -> 8.9 | Q22: Km/L | R22: 748 | S22: 38.84 | T22: 4.84 | U22: 187.99 | V22: 120567811 | W22: Planejamento Operaci | X22: Planejamento Operaci | Y22: Operacional | AA22: =DATEVALUE(C22) -> 45789 | AB22: =MONTH(AA22) -> 5 | AC22: =YEAR(AA22) -> 2025 | AD22: =IFERROR(VLOOKUP(A22,'Aux Área'!$A$4:$B$123,2,0),"-") -> CONSERVA
A23: TFY6E09 | B23: 60645800105124193 | C23: 12/05/2025 19:38:11 | D23: 71805 | E23: MURILLO SOUZA BERNARDES | F23: VA - 04 | G23: Automóvel | H23: ARGO | I23: FIAT | J23: 31860311 | K23: POSTO CAPIM DOURADO | L23: GOIANIA | M23: GO | N23: ETANOL COMUM | O23: =P23*S23 -> 388.8306 | P23: =P42 -> 10.11 | Q23: Km/L | R23: 1378 | S23: 38.46 | T23: 4.79 | U23: 184.22 | V23: 197343 | W23: Planejamento Operaci | X23: Planejamento Operaci | Y23: Operacional | AA23: =DATEVALUE(C23) -> 45789 | AB23: =MONTH(AA23) -> 5 | AC23: =YEAR(AA23) -> 2025 | AD23: =IFERROR(VLOOKUP(A23,'Aux Área'!$A$4:$B$123,2,0),"-") -> ENGENHARIA
A24: TFS3C72 | B24: 60645800105124220 | C24: 13/05/2025 12:44:59 | D24: 00271 | E24: HEDER OLIVEIRA SANTANA | F24: VA - 06 | G24: Automóvel | H24: ARGO | I24: FIAT | J24: 26406711 | K24: POSTO ZANDONADI | L24: GUAPO | M24: GO | N24: ETANOL ADITIVADO | O24: 348 | P24: 8.63 | Q24: Km/L | R24: 2456 | S24: 40.33 | T24: 4.59 | U24: 185.11 | V24: 1 | W24: Planejamento Operaci | X24: Planejamento Operaci | Y24: Operacional | AA24: =DATEVALUE(C24) -> 45790 | AB24: =MONTH(AA24) -> 5 | AC24: =YEAR(AA24) -> 2025 | AD24: =IFERROR(VLOOKUP(A24,'Aux Área'!$A$4:$B$123,2,0),"-") -> CONSERVA
A25: TGF2J32 | B25: 60645800105124310 | C25: 13/05/2025 12:47:36 | D25: 29136 | E25: CLEITON INACIO DE MOURA | F25: VA - 14 | G25: Automóvel | H25: ARGO | I25: FIAT | J25: 31860311 | K25: POSTO CAPIM DOURADO | L25: GOIANIA | M25: GO | N25: ETANOL COMUM | O25: =P25*S25 -> 323.0396 | P25: =P64 -> 9.62 | Q25: Km/L | R25: 692 | S25: 33.58 | T25: 4.79 | U25: 160.84 | V25: 201722 | W25: Planejamento Operaci | X25: Planejamento Operaci | Y25: Operacional | AA25: =DATEVALUE(C25) -> 45790 | AB25: =MONTH(AA25) -> 5 | AC25: =YEAR(AA25) -> 2025 | AD25: =IFERROR(VLOOKUP(A25,'Aux Área'!$A$4:$B$123,2,0),"-") -> TI
A26: TFP3B22 | B26: 60645800105124210 | C26: 13/05/2025 13:33:14 | D26: 02769 | E26: ANDRE LUIS PAULINO | F26: VA - 05 | G26: Automóvel | H26: ARGO | I26: FIAT | J26: 81889412 | K26: POSTO ZERO UM | L26: RIO VERDE | M26: GO | N26: ETANOL COMUM | O26: =P26*S26 -> 363.7767 | P26: =P29 -> 9.33 | Q26: Km/L | R26: 2610 | S26: 38.99 | T26: 4.09 | U26: 159.46 | V26: 0 | W26: Planejamento Operaci | X26: Planejamento Operaci | Y26: Operacional | AA26: =DATEVALUE(C26) -> 45790 | AB26: =MONTH(AA26) -> 5 | AC26: =YEAR(AA26) -> 2025 | AD26: =IFERROR(VLOOKUP(A26,'Aux Área'!$A$4:$B$123,2,0),"-") -> CONSERVA
A27: TFE6B22 | B27: 60645800105124258 | C27: 13/05/2025 14:21:43 | D27: 03608 | E27: WEIDER DA SILVA RODRIGUES | F27: VA - 09 | G27: Automóvel | H27: ARGO | I27: FIAT | J27: 26466212 | K27: AUTO POSTO GLOBAL AR | L27: GOIANIA | M27: GO | N27: ETANOL COMUM | O27: =P27*S27 -> 339.72 | P27: =P84 -> 8.94 | Q27: Km/L | R27: 370 | S27: 38 | T27: 4.841 | U27: 183.96 | V27: 130551651 | W27: Planejamento Operaci | X27: Planejamento Operaci | Y27: Operacional | AA27: =DATEVALUE(C27) -> 45790 | AB27: =MONTH(AA27) -> 5 | AC27: =YEAR(AA27) -> 2025 | AD27: =IFERROR(VLOOKUP(A27,'Aux Área'!$A$4:$B$123,2,0),"-") -> ENGENHARIA
A28: TGL4J09 | B28: 60645800105124150 | C28: 13/05/2025 18:52:46 | D28: 40379 | E28: JESTER LUCAS GOUVEIA SANTOS | F28: VA - 01 | G28: Automóvel | H28: ARGO | I28: FIAT | J28: 88813408 | K28: POSTO ITALIA | L28: SENADOR CANEDO | M28: GO | N28: ETANOL COMUM | O28: =P28*S28 -> 389.0025 | P28: =P80 -> 10.17 | Q28: Km/L | R28: 3329 | S28: 38.25 | T28: 4.79 | U28: 183.22 | V28: 3186 | W28: Planejamento Operaci | X28: Planejamento Operaci | Y28: Operacional | AA28: =DATEVALUE(C28) -> 45790 | AB28: =MONTH(AA28) -> 5 | AC28: =YEAR(AA28) -> 2025 | AD28: =IFERROR(VLOOKUP(A28,'Aux Área'!$A$4:$B$123,2,0),"-") -> ENGENHARIA
A29: TFP3B22 | B29: 60645800105124210 | C29: 14/05/2025 07:33:51 | D29: 02769 | E29: ANDRE LUIS PAULINO | F29: VA - 05 | G29: Automóvel | H29: ARGO | I29: FIAT | J29: 45364511 | K29: AUTO POSTO CERRADO 4 | L29: ITUMBIARA | M29: GO | N29: ETANOL COMUM | O29: 320 | P29: 9.33 | Q29: Km/L | R29: 2930 | S29: 34.29 | T29: 3.99 | U29: 136.82 | V29: 337702 | W29: Planejamento Operaci | X29: Planejamento Operaci | Y29: Operacional | AA29: =DATEVALUE(C29) -> 45791 | AB29: =MONTH(AA29) -> 5 | AC29: =YEAR(AA29) -> 2025 | AD29: =IFERROR(VLOOKUP(A29,'Aux Área'!$A$4:$B$123,2,0),"-") -> CONSERVA
A30: TFY2H52 | B30: 60645800105124282 | C30: 14/05/2025 19:09:57 | D30: 49396 | E30: JOAO JOSE MULATINHO DE MEDEIROS CORREIA | F30: VA - 12 | G30: Automóvel | H30: ARGO | I30: FIAT | J30: 36603412 | K30: POSTO DO RATINHO | L30: GOIANIA | M30: GO | N30: ETANOL COMUM | O30: =P30*S30 -> 455.2548 | P30: =P43 -> 11.37 | Q30: Km/L | R30: 1214 | S30: 40.04 | T30: 5.083 | U30: 203.52 | V30: 0 | W30: Planejamento Operaci | X30: Planejamento Operaci | Y30: Operacional | AA30: =DATEVALUE(C30) -> 45791 | AB30: =MONTH(AA30) -> 5 | AC30: =YEAR(AA30) -> 2025 | AD30: =IFERROR(VLOOKUP(A30,'Aux Área'!$A$4:$B$123,2,0),"-") -> QSMS
A31: TFY3C02 | B31: 60645800105124266 | C31: 14/05/2025 21:53:35 | D31: 37473 | E31: OTHON SIQUEIRA DE ALMEIDA | F31: VA - 10 | G31: Automóvel | H31: ARGO | I31: FIAT | J31: 07506503 | K31: POSTO CHURR. PRESIDENTE 24HS | L31: ANAPOLIS | M31: GO | N31: ETANOL COMUM | O31: =P31*S31 -> 377.8921 | P31: =P53 -> 9.37 | Q31: Km/L | R31: 2002 | S31: 40.33 | T31: 4.29 | U31: 173.02 | V31: 1 | W31: Planejamento Operaci | X31: Planejamento Operaci | Y31: Operacional | AA31: =DATEVALUE(C31) -> 45791 | AB31: =MONTH(AA31) -> 5 | AC31: =YEAR(AA31) -> 2025 | AD31: =IFERROR(VLOOKUP(A31,'Aux Área'!$A$4:$B$123,2,0),"-") -> OPERAÇÃO
A32: TFX7J72 | B32: 60645800105124339 | C32: 15/05/2025 07:03:32 | D32: 03126 | E32: PEDRO PAULO SILVA SANTOS | F32: VA - 08 | G32: Automóvel | H32: ARGO | I32: FIAT | J32: 75350202 | K32: AUTO POSTO SANTA FE BAIRRO POP | L32: RIO VERDE | M32: GO | N32: ETANOL COMUM | O32: =P32*S32 -> 277.3848 | P32: =P50 -> 8.69 | Q32: Km/L | R32: 2887 | S32: 31.92 | T32: 4.341 | U32: 138.55 | V32: 3 | W32: Planejamento Operaci | X32: Planejamento Operaci | Y32: Operacional | AA32: =DATEVALUE(C32) -> 45792 | AB32: =MONTH(AA32) -> 5 | AC32: =YEAR(AA32) -> 2025 | AD32: =IFERROR(VLOOKUP(A32,'Aux Área'!$A$4:$B$123,2,0),"-") -> CONSERVA
A33: TFS3C72 | B33: 60645800105124220 | C33: 15/05/2025 08:22:48 | D33: 00271 | E33: HEDER OLIVEIRA SANTANA | F33: VA - 06 | G33: Automóvel | H33: ARGO | I33: FIAT | J33: 81889412 | K33: POSTO ZERO UM | L33: RIO VERDE | M33: GO | N33: ETANOL COMUM | O33: 335 | P33: 8.5 | Q33: Km/L | R33: 2791 | S33: 39.4 | T33: 4.099 | U33: 161.5 | V33: 1 | W33: Planejamento Operaci | X33: Planejamento Operaci | Y33: Operacional | AA33: =DATEVALUE(C33) -> 45792 | AB33: =MONTH(AA33) -> 5 | AC33: =YEAR(AA33) -> 2025 | AD33: =IFERROR(VLOOKUP(A33,'Aux Área'!$A$4:$B$123,2,0),"-") -> CONSERVA
A34: TFP3B22 | B34: 60645800105124210 | C34: 15/05/2025 08:54:34 | D34: 02769 | E34: ANDRE LUIS PAULINO | F34: VA - 05 | G34: Automóvel | H34: ARGO | I34: FIAT | J34: 46286315 | K34: POSTO CENTRAL | L34: BOM JESUS | M34: GO | N34: ETANOL COMUM | O34: 325 | P34: 9.67 | Q34: Km/L | R34: 3255 | S34: 33.62 | T34: 4.461 | U34: 149.98 | V34: 1 | W34: Planejamento Operaci | X34: Planejamento Operaci | Y34: Operacional | AA34: =DATEVALUE(C34) -> 45792 | AB34: =MONTH(AA34) -> 5 | AC34: =YEAR(AA34) -> 2025 | AD34: =IFERROR(VLOOKUP(A34,'Aux Área'!$A$4:$B$123,2,0),"-") -> CONSERVA
A35: TFS3C72 | B35: 60645800105124220 | C35: 15/05/2025 16:05:05 | D35: 00271 | E35: HEDER OLIVEIRA SANTANA | F35: VA - 06 | G35: Automóvel | H35: ARGO | I35: FIAT | J35: 75331003 | K35: SUPERVIA LAGOA | L35: RIO VERDE | M35: GO | N35: ETANOL COMUM | O35: 352 | P35: 8.59 | Q35: Km/L | R35: 3143 | S35: 40.96 | T35: 3.79 | U35: 155.24 | V35: 0 | W35: Planejamento Operaci | X35: Planejamento Operaci | Y35: Operacional | AA35: =DATEVALUE(C35) -> 45792 | AB35: =MONTH(AA35) -> 5 | AC35: =YEAR(AA35) -> 2025 | AD35: =IFERROR(VLOOKUP(A35,'Aux Área'!$A$4:$B$123,2,0),"-") -> CONSERVA
A36: TFP9I32 | B36: 60645800105124300 | C36: 15/05/2025 16:20:29 | D36: 33861 | E36: FERNANDO DOS REIS GONÇALVES | F36: VA - 13 | G36: Automóvel | H36: ARGO | I36: FIAT | J36: 69494411 | K36: REDE MARAJO RIO VERD | L36: RIO VERDE | M36: GO | N36: ETANOL COMUM | O36: 365 | P36: 8.9 | Q36: Km/L | R36: 1113 | S36: 41 | T36: 4.19 | U36: 171.79 | V36: 1 | W36: Planejamento Operaci | X36: Planejamento Operaci | Y36: Operacional | AA36: =DATEVALUE(C36) -> 45792 | AB36: =MONTH(AA36) -> 5 | AC36: =YEAR(AA36) -> 2025 | AD36: =IFERROR(VLOOKUP(A36,'Aux Área'!$A$4:$B$123,2,0),"-") -> CONSERVA
A37: TFP3B22 | B37: 60645800105124210 | C37: 16/05/2025 08:24:03 | D37: 02769 | E37: ANDRE LUIS PAULINO | F37: VA - 05 | G37: Automóvel | H37: ARGO | I37: FIAT | J37: 53030006 | K37: KR TREVO | L37: SANTA HELENA DE GOIAS | M37: GO | N37: ETANOL COMUM | O37: 383 | P37: 9.85 | Q37: Km/L | R37: 3638 | S37: 38.87 | T37: 4.29 | U37: 166.75 | V37: 1 | W37: Planejamento Operaci | X37: Planejamento Operaci | Y37: Operacional | AA37: =DATEVALUE(C37) -> 45793 | AB37: =MONTH(AA37) -> 5 | AC37: =YEAR(AA37) -> 2025 | AD37: =IFERROR(VLOOKUP(A37,'Aux Área'!$A$4:$B$123,2,0),"-") -> CONSERVA
A38: TFE6B22 | B38: 60645800105124258 | C38: 16/05/2025 08:53:50 | D38: 03608 | E38: WEIDER DA SILVA RODRIGUES | F38: VA - 09 | G38: Automóvel | H38: ARGO | I38: FIAT | J38: 64170105 | K38: POSTOS DUME | L38: APARECIDA DE GOIANIA | M38: GO | N38: ETANOL COMUM | O38: 444 | P38: 11.58 | Q38: Km/L | R38: 814 | S38: 38.35 | T38: 4.741 | U38: 181.81 | V38: 12 | W38: Planejamento Operaci | X38: Planejamento Operaci | Y38: Operacional | AA38: =DATEVALUE(C38) -> 45793 | AB38: =MONTH(AA38) -> 5 | AC38: =YEAR(AA38) -> 2025 | AD38: =IFERROR(VLOOKUP(A38,'Aux Área'!$A$4:$B$123,2,0),"-") -> ENGENHARIA
A39: TFX8A49 | B39: 60645800105124169 | C39: 16/05/2025 10:32:03 | D39: 70882 | E39: EDUARDO DE SOUSA PIMENTEL | F39: POOL - 01 | G39: Automóvel | H39: ARGO | I39: FIAT | J39: 26466212 | K39: AUTO POSTO GLOBAL AR | L39: GOIANIA | M39: GO | N39: ETANOL COMUM | O39: =P39*S39 -> 260.0307 | P39: =P155 -> 7.47 | Q39: Km/L | R39: 1325 | S39: 34.81 | T39: 4.84 | U39: 168.48 | V39: 160537867 | W39: Planejamento Operaci | X39: Planejamento Operaci | Y39: Operacional | AA39: =DATEVALUE(C39) -> 45793 | AB39: =MONTH(AA39) -> 5 | AC39: =YEAR(AA39) -> 2025 | AD39: =IFERROR(VLOOKUP(A39,'Aux Área'!$A$4:$B$123,2,0),"-") -> OPERAÇÃO
A40: TFS3C72 | B40: 60645800105124220 | C40: 16/05/2025 14:28:43 | D40: 00271 | E40: HEDER OLIVEIRA SANTANA | F40: VA - 06 | G40: Automóvel | H40: ARGO | I40: FIAT | J40: 45308900 | K40: POSTO LUPATINI | L40: SANTO ANTONIO DA BARRA | M40: GO | N40: ETANOL COMUM | O40: 268 | P40: 8.9 | Q40: Km/L | R40: 3411 | S40: 30.11 | T40: 4.39 | U40: 132.18 | V40: 0 | W40: Planejamento Operaci | X40: Planejamento Operaci | Y40: Operacional | AA40: =DATEVALUE(C40) -> 45793 | AB40: =MONTH(AA40) -> 5 | AC40: =YEAR(AA40) -> 2025 | AD40: =IFERROR(VLOOKUP(A40,'Aux Área'!$A$4:$B$123,2,0),"-") -> CONSERVA
...

Sheet Aux Área
A3: Id | B3: Área | C3: Tipo
A4: TFB0B52 | B4: ANTT | C4: FISCALIZAÇÃO
A5: TGJ8F72 | B5: ANTT | C5: ANTT
A6: TFE9C14 | B6: APH
A7: TFL8I14 | B7: APH
A8: TFM4H34 | B8: APH
A9: TFN3B64 | B9: APH
A10: TFU6C04 | B10: APH
A11: TFV8C74 | B11: APH
A12: TFW3J34 | B12: APH
A13: TGC9A34 | B13: APH
A14: TGE1F64 | B14: APH
A15: TGL2B04 | B15: APH
A16: TFP3B22 | B16: CONSERVA
A17: TFP9I32 | B17: CONSERVA
... A46: TUW2D74 | B46: INSPEÇÃO
A47: TTV4H65 | B47: INSPEÇÃO | C47: IT-14
A48: TUQ2H91 | B48: INSPEÇÃO | C48: IT-13
A49: SCX7I02 | B49: JURÍDICO
A50: TFO4A43 | B50: JURÍDICO
A51: TLR1J91 | B51: LUCCA JR - OP
A52: TFD2J89 | B52: OPERAÇÃO | C52: POOL-02
A53: TFF5D72 | B53: OPERAÇÃO | C53: VA-11
A54: TFI3B19 | B54: OPERAÇÃO | C54: VA-03
A55: TFX8A49 | B55: OPERAÇÃO | C55: POOL-01
A56: TFY3C02 | B56: OPERAÇÃO | C56: VA-10
A57: TIV6G27 | B57: PESADOS | C57: GUINCHO LEVE
A58: TJE5D27 | B58: PESADOS | C58: GUINCHO LEVE
A59: TJP1H27 | B59: PESADOS | C59: GUINCHO LEVE
A60: TKB0E17 | B60: PESADOS | C60: GUINCHO LEVE
A61: TKC7D89 | B61: PESADOS | C61: GUINCHO PESADO
A62: TKC9B59 | B62: PESADOS | C62: GUINCHO PESADO
